{
 "cells": [
  {
   "cell_type": "code",
   "execution_count": 24,
   "metadata": {},
   "outputs": [],
   "source": [
    "%%capture\n",
    "%load_ext sql\n"
   ]
  },
  {
   "cell_type": "code",
   "execution_count": 25,
   "metadata": {},
   "outputs": [
    {
     "name": "stdout",
     "output_type": "stream",
     "text": [
      "Traceback (most recent call last):\n",
      "  File \"/home/codespace/.python/current/lib/python3.12/site-packages/sqlalchemy/engine/base.py\", line 146, in __init__\n",
      "    self._dbapi_connection = engine.raw_connection()\n",
      "                             ^^^^^^^^^^^^^^^^^^^^^^^\n",
      "  File \"/home/codespace/.python/current/lib/python3.12/site-packages/sqlalchemy/engine/base.py\", line 3302, in raw_connection\n",
      "    return self.pool.connect()\n",
      "           ^^^^^^^^^^^^^^^^^^^\n",
      "  File \"/home/codespace/.python/current/lib/python3.12/site-packages/sqlalchemy/pool/base.py\", line 449, in connect\n",
      "    return _ConnectionFairy._checkout(self)\n",
      "           ^^^^^^^^^^^^^^^^^^^^^^^^^^^^^^^^\n",
      "  File \"/home/codespace/.python/current/lib/python3.12/site-packages/sqlalchemy/pool/base.py\", line 1263, in _checkout\n",
      "    fairy = _ConnectionRecord.checkout(pool)\n",
      "            ^^^^^^^^^^^^^^^^^^^^^^^^^^^^^^^^\n",
      "  File \"/home/codespace/.python/current/lib/python3.12/site-packages/sqlalchemy/pool/base.py\", line 712, in checkout\n",
      "    rec = pool._do_get()\n",
      "          ^^^^^^^^^^^^^^\n",
      "  File \"/home/codespace/.python/current/lib/python3.12/site-packages/sqlalchemy/pool/impl.py\", line 179, in _do_get\n",
      "    with util.safe_reraise():\n",
      "  File \"/home/codespace/.python/current/lib/python3.12/site-packages/sqlalchemy/util/langhelpers.py\", line 146, in __exit__\n",
      "    raise exc_value.with_traceback(exc_tb)\n",
      "  File \"/home/codespace/.python/current/lib/python3.12/site-packages/sqlalchemy/pool/impl.py\", line 177, in _do_get\n",
      "    return self._create_connection()\n",
      "           ^^^^^^^^^^^^^^^^^^^^^^^^^\n",
      "  File \"/home/codespace/.python/current/lib/python3.12/site-packages/sqlalchemy/pool/base.py\", line 390, in _create_connection\n",
      "    return _ConnectionRecord(self)\n",
      "           ^^^^^^^^^^^^^^^^^^^^^^^\n",
      "  File \"/home/codespace/.python/current/lib/python3.12/site-packages/sqlalchemy/pool/base.py\", line 674, in __init__\n",
      "    self.__connect()\n",
      "  File \"/home/codespace/.python/current/lib/python3.12/site-packages/sqlalchemy/pool/base.py\", line 900, in __connect\n",
      "    with util.safe_reraise():\n",
      "  File \"/home/codespace/.python/current/lib/python3.12/site-packages/sqlalchemy/util/langhelpers.py\", line 146, in __exit__\n",
      "    raise exc_value.with_traceback(exc_tb)\n",
      "  File \"/home/codespace/.python/current/lib/python3.12/site-packages/sqlalchemy/pool/base.py\", line 896, in __connect\n",
      "    self.dbapi_connection = connection = pool._invoke_creator(self)\n",
      "                                         ^^^^^^^^^^^^^^^^^^^^^^^^^^\n",
      "  File \"/home/codespace/.python/current/lib/python3.12/site-packages/sqlalchemy/engine/create.py\", line 643, in connect\n",
      "    return dialect.connect(*cargs, **cparams)\n",
      "           ^^^^^^^^^^^^^^^^^^^^^^^^^^^^^^^^^^\n",
      "  File \"/home/codespace/.python/current/lib/python3.12/site-packages/sqlalchemy/engine/default.py\", line 621, in connect\n",
      "    return self.loaded_dbapi.connect(*cargs, **cparams)\n",
      "           ^^^^^^^^^^^^^^^^^^^^^^^^^^^^^^^^^^^^^^^^^^^^\n",
      "  File \"/home/codespace/.python/current/lib/python3.12/site-packages/psycopg2/__init__.py\", line 122, in connect\n",
      "    conn = _connect(dsn, connection_factory=connection_factory, **kwasync)\n",
      "           ^^^^^^^^^^^^^^^^^^^^^^^^^^^^^^^^^^^^^^^^^^^^^^^^^^^^^^^^^^^^^^^\n",
      "psycopg2.OperationalError: connection to server on socket \"/var/run/postgresql/.s.PGSQL.5432\" failed: No such file or directory\n",
      "\tIs the server running locally and accepting connections on that socket?\n",
      "\n",
      "\n",
      "The above exception was the direct cause of the following exception:\n",
      "\n",
      "Traceback (most recent call last):\n",
      "  File \"/home/codespace/.python/current/lib/python3.12/site-packages/sql/magic.py\", line 196, in execute\n",
      "    conn = sql.connection.Connection.set(\n",
      "           ^^^^^^^^^^^^^^^^^^^^^^^^^^^^^^\n",
      "  File \"/home/codespace/.python/current/lib/python3.12/site-packages/sql/connection.py\", line 70, in set\n",
      "    cls.current = existing or Connection(descriptor, connect_args, creator)\n",
      "                              ^^^^^^^^^^^^^^^^^^^^^^^^^^^^^^^^^^^^^^^^^^^^^\n",
      "  File \"/home/codespace/.python/current/lib/python3.12/site-packages/sql/connection.py\", line 55, in __init__\n",
      "    self.internal_connection = engine.connect()\n",
      "                               ^^^^^^^^^^^^^^^^\n",
      "  File \"/home/codespace/.python/current/lib/python3.12/site-packages/sqlalchemy/engine/base.py\", line 3278, in connect\n",
      "    return self._connection_cls(self)\n",
      "           ^^^^^^^^^^^^^^^^^^^^^^^^^^\n",
      "  File \"/home/codespace/.python/current/lib/python3.12/site-packages/sqlalchemy/engine/base.py\", line 148, in __init__\n",
      "    Connection._handle_dbapi_exception_noconnection(\n",
      "  File \"/home/codespace/.python/current/lib/python3.12/site-packages/sqlalchemy/engine/base.py\", line 2442, in _handle_dbapi_exception_noconnection\n",
      "    raise sqlalchemy_exception.with_traceback(exc_info[2]) from e\n",
      "  File \"/home/codespace/.python/current/lib/python3.12/site-packages/sqlalchemy/engine/base.py\", line 146, in __init__\n",
      "    self._dbapi_connection = engine.raw_connection()\n",
      "                             ^^^^^^^^^^^^^^^^^^^^^^^\n",
      "  File \"/home/codespace/.python/current/lib/python3.12/site-packages/sqlalchemy/engine/base.py\", line 3302, in raw_connection\n",
      "    return self.pool.connect()\n",
      "           ^^^^^^^^^^^^^^^^^^^\n",
      "  File \"/home/codespace/.python/current/lib/python3.12/site-packages/sqlalchemy/pool/base.py\", line 449, in connect\n",
      "    return _ConnectionFairy._checkout(self)\n",
      "           ^^^^^^^^^^^^^^^^^^^^^^^^^^^^^^^^\n",
      "  File \"/home/codespace/.python/current/lib/python3.12/site-packages/sqlalchemy/pool/base.py\", line 1263, in _checkout\n",
      "    fairy = _ConnectionRecord.checkout(pool)\n",
      "            ^^^^^^^^^^^^^^^^^^^^^^^^^^^^^^^^\n",
      "  File \"/home/codespace/.python/current/lib/python3.12/site-packages/sqlalchemy/pool/base.py\", line 712, in checkout\n",
      "    rec = pool._do_get()\n",
      "          ^^^^^^^^^^^^^^\n",
      "  File \"/home/codespace/.python/current/lib/python3.12/site-packages/sqlalchemy/pool/impl.py\", line 179, in _do_get\n",
      "    with util.safe_reraise():\n",
      "  File \"/home/codespace/.python/current/lib/python3.12/site-packages/sqlalchemy/util/langhelpers.py\", line 146, in __exit__\n",
      "    raise exc_value.with_traceback(exc_tb)\n",
      "  File \"/home/codespace/.python/current/lib/python3.12/site-packages/sqlalchemy/pool/impl.py\", line 177, in _do_get\n",
      "    return self._create_connection()\n",
      "           ^^^^^^^^^^^^^^^^^^^^^^^^^\n",
      "  File \"/home/codespace/.python/current/lib/python3.12/site-packages/sqlalchemy/pool/base.py\", line 390, in _create_connection\n",
      "    return _ConnectionRecord(self)\n",
      "           ^^^^^^^^^^^^^^^^^^^^^^^\n",
      "  File \"/home/codespace/.python/current/lib/python3.12/site-packages/sqlalchemy/pool/base.py\", line 674, in __init__\n",
      "    self.__connect()\n",
      "  File \"/home/codespace/.python/current/lib/python3.12/site-packages/sqlalchemy/pool/base.py\", line 900, in __connect\n",
      "    with util.safe_reraise():\n",
      "  File \"/home/codespace/.python/current/lib/python3.12/site-packages/sqlalchemy/util/langhelpers.py\", line 146, in __exit__\n",
      "    raise exc_value.with_traceback(exc_tb)\n",
      "  File \"/home/codespace/.python/current/lib/python3.12/site-packages/sqlalchemy/pool/base.py\", line 896, in __connect\n",
      "    self.dbapi_connection = connection = pool._invoke_creator(self)\n",
      "                                         ^^^^^^^^^^^^^^^^^^^^^^^^^^\n",
      "  File \"/home/codespace/.python/current/lib/python3.12/site-packages/sqlalchemy/engine/create.py\", line 643, in connect\n",
      "    return dialect.connect(*cargs, **cparams)\n",
      "           ^^^^^^^^^^^^^^^^^^^^^^^^^^^^^^^^^^\n",
      "  File \"/home/codespace/.python/current/lib/python3.12/site-packages/sqlalchemy/engine/default.py\", line 621, in connect\n",
      "    return self.loaded_dbapi.connect(*cargs, **cparams)\n",
      "           ^^^^^^^^^^^^^^^^^^^^^^^^^^^^^^^^^^^^^^^^^^^^\n",
      "  File \"/home/codespace/.python/current/lib/python3.12/site-packages/psycopg2/__init__.py\", line 122, in connect\n",
      "    conn = _connect(dsn, connection_factory=connection_factory, **kwasync)\n",
      "           ^^^^^^^^^^^^^^^^^^^^^^^^^^^^^^^^^^^^^^^^^^^^^^^^^^^^^^^^^^^^^^^\n",
      "sqlalchemy.exc.OperationalError: (psycopg2.OperationalError) connection to server on socket \"/var/run/postgresql/.s.PGSQL.5432\" failed: No such file or directory\n",
      "\tIs the server running locally and accepting connections on that socket?\n",
      "\n",
      "(Background on this error at: https://sqlalche.me/e/20/e3q8)\n",
      "\n",
      "Connection info needed in SQLAlchemy format, example:\n",
      "               postgresql://username:password@hostname/dbname\n",
      "               or an existing connection: dict_keys([])\n"
     ]
    }
   ],
   "source": [
    "%sql postgresql:///ai_data SELECT * FROM ai_data LIMIT 10"
   ]
  },
  {
   "cell_type": "code",
   "execution_count": 28,
   "metadata": {},
   "outputs": [
    {
     "name": "stdout",
     "output_type": "stream",
     "text": [
      "Traceback (most recent call last):\n",
      "  File \"/home/codespace/.python/current/lib/python3.12/site-packages/sqlalchemy/engine/base.py\", line 146, in __init__\n",
      "    self._dbapi_connection = engine.raw_connection()\n",
      "                             ^^^^^^^^^^^^^^^^^^^^^^^\n",
      "  File \"/home/codespace/.python/current/lib/python3.12/site-packages/sqlalchemy/engine/base.py\", line 3302, in raw_connection\n",
      "    return self.pool.connect()\n",
      "           ^^^^^^^^^^^^^^^^^^^\n",
      "  File \"/home/codespace/.python/current/lib/python3.12/site-packages/sqlalchemy/pool/base.py\", line 449, in connect\n",
      "    return _ConnectionFairy._checkout(self)\n",
      "           ^^^^^^^^^^^^^^^^^^^^^^^^^^^^^^^^\n",
      "  File \"/home/codespace/.python/current/lib/python3.12/site-packages/sqlalchemy/pool/base.py\", line 1263, in _checkout\n",
      "    fairy = _ConnectionRecord.checkout(pool)\n",
      "            ^^^^^^^^^^^^^^^^^^^^^^^^^^^^^^^^\n",
      "  File \"/home/codespace/.python/current/lib/python3.12/site-packages/sqlalchemy/pool/base.py\", line 712, in checkout\n",
      "    rec = pool._do_get()\n",
      "          ^^^^^^^^^^^^^^\n",
      "  File \"/home/codespace/.python/current/lib/python3.12/site-packages/sqlalchemy/pool/impl.py\", line 179, in _do_get\n",
      "    with util.safe_reraise():\n",
      "  File \"/home/codespace/.python/current/lib/python3.12/site-packages/sqlalchemy/util/langhelpers.py\", line 146, in __exit__\n",
      "    raise exc_value.with_traceback(exc_tb)\n",
      "  File \"/home/codespace/.python/current/lib/python3.12/site-packages/sqlalchemy/pool/impl.py\", line 177, in _do_get\n",
      "    return self._create_connection()\n",
      "           ^^^^^^^^^^^^^^^^^^^^^^^^^\n",
      "  File \"/home/codespace/.python/current/lib/python3.12/site-packages/sqlalchemy/pool/base.py\", line 390, in _create_connection\n",
      "    return _ConnectionRecord(self)\n",
      "           ^^^^^^^^^^^^^^^^^^^^^^^\n",
      "  File \"/home/codespace/.python/current/lib/python3.12/site-packages/sqlalchemy/pool/base.py\", line 674, in __init__\n",
      "    self.__connect()\n",
      "  File \"/home/codespace/.python/current/lib/python3.12/site-packages/sqlalchemy/pool/base.py\", line 900, in __connect\n",
      "    with util.safe_reraise():\n",
      "  File \"/home/codespace/.python/current/lib/python3.12/site-packages/sqlalchemy/util/langhelpers.py\", line 146, in __exit__\n",
      "    raise exc_value.with_traceback(exc_tb)\n",
      "  File \"/home/codespace/.python/current/lib/python3.12/site-packages/sqlalchemy/pool/base.py\", line 896, in __connect\n",
      "    self.dbapi_connection = connection = pool._invoke_creator(self)\n",
      "                                         ^^^^^^^^^^^^^^^^^^^^^^^^^^\n",
      "  File \"/home/codespace/.python/current/lib/python3.12/site-packages/sqlalchemy/engine/create.py\", line 643, in connect\n",
      "    return dialect.connect(*cargs, **cparams)\n",
      "           ^^^^^^^^^^^^^^^^^^^^^^^^^^^^^^^^^^\n",
      "  File \"/home/codespace/.python/current/lib/python3.12/site-packages/sqlalchemy/engine/default.py\", line 621, in connect\n",
      "    return self.loaded_dbapi.connect(*cargs, **cparams)\n",
      "           ^^^^^^^^^^^^^^^^^^^^^^^^^^^^^^^^^^^^^^^^^^^^\n",
      "  File \"/home/codespace/.python/current/lib/python3.12/site-packages/psycopg2/__init__.py\", line 122, in connect\n",
      "    conn = _connect(dsn, connection_factory=connection_factory, **kwasync)\n",
      "           ^^^^^^^^^^^^^^^^^^^^^^^^^^^^^^^^^^^^^^^^^^^^^^^^^^^^^^^^^^^^^^^\n",
      "psycopg2.OperationalError: connection to server on socket \"/var/run/postgresql/.s.PGSQL.5432\" failed: No such file or directory\n",
      "\tIs the server running locally and accepting connections on that socket?\n",
      "\n",
      "\n",
      "The above exception was the direct cause of the following exception:\n",
      "\n",
      "Traceback (most recent call last):\n",
      "  File \"/home/codespace/.python/current/lib/python3.12/site-packages/sql/magic.py\", line 196, in execute\n",
      "    conn = sql.connection.Connection.set(\n",
      "           ^^^^^^^^^^^^^^^^^^^^^^^^^^^^^^\n",
      "  File \"/home/codespace/.python/current/lib/python3.12/site-packages/sql/connection.py\", line 70, in set\n",
      "    cls.current = existing or Connection(descriptor, connect_args, creator)\n",
      "                              ^^^^^^^^^^^^^^^^^^^^^^^^^^^^^^^^^^^^^^^^^^^^^\n",
      "  File \"/home/codespace/.python/current/lib/python3.12/site-packages/sql/connection.py\", line 55, in __init__\n",
      "    self.internal_connection = engine.connect()\n",
      "                               ^^^^^^^^^^^^^^^^\n",
      "  File \"/home/codespace/.python/current/lib/python3.12/site-packages/sqlalchemy/engine/base.py\", line 3278, in connect\n",
      "    return self._connection_cls(self)\n",
      "           ^^^^^^^^^^^^^^^^^^^^^^^^^^\n",
      "  File \"/home/codespace/.python/current/lib/python3.12/site-packages/sqlalchemy/engine/base.py\", line 148, in __init__\n",
      "    Connection._handle_dbapi_exception_noconnection(\n",
      "  File \"/home/codespace/.python/current/lib/python3.12/site-packages/sqlalchemy/engine/base.py\", line 2442, in _handle_dbapi_exception_noconnection\n",
      "    raise sqlalchemy_exception.with_traceback(exc_info[2]) from e\n",
      "  File \"/home/codespace/.python/current/lib/python3.12/site-packages/sqlalchemy/engine/base.py\", line 146, in __init__\n",
      "    self._dbapi_connection = engine.raw_connection()\n",
      "                             ^^^^^^^^^^^^^^^^^^^^^^^\n",
      "  File \"/home/codespace/.python/current/lib/python3.12/site-packages/sqlalchemy/engine/base.py\", line 3302, in raw_connection\n",
      "    return self.pool.connect()\n",
      "           ^^^^^^^^^^^^^^^^^^^\n",
      "  File \"/home/codespace/.python/current/lib/python3.12/site-packages/sqlalchemy/pool/base.py\", line 449, in connect\n",
      "    return _ConnectionFairy._checkout(self)\n",
      "           ^^^^^^^^^^^^^^^^^^^^^^^^^^^^^^^^\n",
      "  File \"/home/codespace/.python/current/lib/python3.12/site-packages/sqlalchemy/pool/base.py\", line 1263, in _checkout\n",
      "    fairy = _ConnectionRecord.checkout(pool)\n",
      "            ^^^^^^^^^^^^^^^^^^^^^^^^^^^^^^^^\n",
      "  File \"/home/codespace/.python/current/lib/python3.12/site-packages/sqlalchemy/pool/base.py\", line 712, in checkout\n",
      "    rec = pool._do_get()\n",
      "          ^^^^^^^^^^^^^^\n",
      "  File \"/home/codespace/.python/current/lib/python3.12/site-packages/sqlalchemy/pool/impl.py\", line 179, in _do_get\n",
      "    with util.safe_reraise():\n",
      "  File \"/home/codespace/.python/current/lib/python3.12/site-packages/sqlalchemy/util/langhelpers.py\", line 146, in __exit__\n",
      "    raise exc_value.with_traceback(exc_tb)\n",
      "  File \"/home/codespace/.python/current/lib/python3.12/site-packages/sqlalchemy/pool/impl.py\", line 177, in _do_get\n",
      "    return self._create_connection()\n",
      "           ^^^^^^^^^^^^^^^^^^^^^^^^^\n",
      "  File \"/home/codespace/.python/current/lib/python3.12/site-packages/sqlalchemy/pool/base.py\", line 390, in _create_connection\n",
      "    return _ConnectionRecord(self)\n",
      "           ^^^^^^^^^^^^^^^^^^^^^^^\n",
      "  File \"/home/codespace/.python/current/lib/python3.12/site-packages/sqlalchemy/pool/base.py\", line 674, in __init__\n",
      "    self.__connect()\n",
      "  File \"/home/codespace/.python/current/lib/python3.12/site-packages/sqlalchemy/pool/base.py\", line 900, in __connect\n",
      "    with util.safe_reraise():\n",
      "  File \"/home/codespace/.python/current/lib/python3.12/site-packages/sqlalchemy/util/langhelpers.py\", line 146, in __exit__\n",
      "    raise exc_value.with_traceback(exc_tb)\n",
      "  File \"/home/codespace/.python/current/lib/python3.12/site-packages/sqlalchemy/pool/base.py\", line 896, in __connect\n",
      "    self.dbapi_connection = connection = pool._invoke_creator(self)\n",
      "                                         ^^^^^^^^^^^^^^^^^^^^^^^^^^\n",
      "  File \"/home/codespace/.python/current/lib/python3.12/site-packages/sqlalchemy/engine/create.py\", line 643, in connect\n",
      "    return dialect.connect(*cargs, **cparams)\n",
      "           ^^^^^^^^^^^^^^^^^^^^^^^^^^^^^^^^^^\n",
      "  File \"/home/codespace/.python/current/lib/python3.12/site-packages/sqlalchemy/engine/default.py\", line 621, in connect\n",
      "    return self.loaded_dbapi.connect(*cargs, **cparams)\n",
      "           ^^^^^^^^^^^^^^^^^^^^^^^^^^^^^^^^^^^^^^^^^^^^\n",
      "  File \"/home/codespace/.python/current/lib/python3.12/site-packages/psycopg2/__init__.py\", line 122, in connect\n",
      "    conn = _connect(dsn, connection_factory=connection_factory, **kwasync)\n",
      "           ^^^^^^^^^^^^^^^^^^^^^^^^^^^^^^^^^^^^^^^^^^^^^^^^^^^^^^^^^^^^^^^\n",
      "sqlalchemy.exc.OperationalError: (psycopg2.OperationalError) connection to server on socket \"/var/run/postgresql/.s.PGSQL.5432\" failed: No such file or directory\n",
      "\tIs the server running locally and accepting connections on that socket?\n",
      "\n",
      "(Background on this error at: https://sqlalche.me/e/20/e3q8)\n",
      "\n",
      "Connection info needed in SQLAlchemy format, example:\n",
      "               postgresql://username:password@hostname/dbname\n",
      "               or an existing connection: dict_keys([])\n"
     ]
    }
   ],
   "source": [
    "%%sql\n",
    "postgresql:///ai_data\n",
    "\n",
    "    SELECT *\n",
    "    FROM ai_data\n",
    "    LIMIT 10\n"
   ]
  }
 ],
 "metadata": {
  "kernelspec": {
   "display_name": "Python 3",
   "language": "python",
   "name": "python3"
  },
  "language_info": {
   "codemirror_mode": {
    "name": "ipython",
    "version": 3
   },
   "file_extension": ".py",
   "mimetype": "text/x-python",
   "name": "python",
   "nbconvert_exporter": "python",
   "pygments_lexer": "ipython3",
   "version": "3.12.1"
  }
 },
 "nbformat": 4,
 "nbformat_minor": 2
}
